<?xml version="1.0" ?>
<!-- =================================================================================== -->
<!-- |    This document was autogenerated by xacro from car_x.xacro                    | -->
<!-- |    EDITING THIS FILE BY HAND IS NOT RECOMMENDED                                 | -->
<!-- =================================================================================== -->
<robot name="fourwheelrobot" xmlns:xacro="http://www.ros.org/wiki/xacro">
  <!-- Base link -->
  <link name="base_link">
    <visual>
      <origin rpy="0 0 0" xyz="0 0 0.1"/>
      <geometry>
        <box size="1 0.5 0.35"/>
      </geometry>
      <material name="yellow">
        <color rgba="0.8 0.8 0 1"/>
      </material>
    </visual>
  </link>
  <link name="f_r_wheel">
    <inertial>
      <origin rpy="1.570795 0 0" xyz="0 0 0"/>
      <mass value="1.0"/>
      <inertia ixx="0.0" ixy="0.0" ixz="0.0" iyy="0.0" iyz="0.0" izz="0.0"/>
    </inertial>
    <visual name="">
      <origin rpy="1.570795 0 0" xyz="0 0 0"/>
      <geometry>
        <cylinder length="0.1" radius="0.2"/>
      </geometry>
      <material name="black">
        <color rgba="0.05 0.05 0.05 1"/>
        <texture filename=""/>
      </material>
    </visual>
    <collision>
      <origin rpy="1.570795 0 0" xyz="0 0 0"/>
      <geometry>
        <cylinder length="0.1" radius="0.2"/>
      </geometry>
    </collision>
  </link>
  <joint name="joint_f_r_wheel" type="continuous">
    <parent link="base_link"/>
    <child link="f_r_wheel"/>
    <origin rpy="0 0 0" xyz="0.25 -0.30 0"/>
    <axis rpy="0 0 0" xyz="0 1 0"/>
  </joint>
  <gazebo reference="f_r_wheel_trans_gaz">
    <mu1 value="200.0"/>
    <mu2 value="100.0"/>
    <kp value="10000000.0"/>
    <kd value="1.0"/>
    <material>Gazebo/Grey</material>
  </gazebo>
  <transmission name="trnasm_f_r_wheel">
    <type>transmission_interface/SimpleTransmission</type>
    <actuator name="$act_f_r_wheel">
      <mechanicalReduction>1</mechanicalReduction>
    </actuator>
    <joint name="joint_f_r_wheel">
      <hardwareInterface>VelocityJointInterface</hardwareInterface>
    </joint>
  </transmission>
  <link name="b_r_wheel">
    <inertial>
      <origin rpy="1.570795 0 0" xyz="0 0 0"/>
      <mass value="1.0"/>
      <inertia ixx="0.0" ixy="0.0" ixz="0.0" iyy="0.0" iyz="0.0" izz="0.0"/>
    </inertial>
    <visual name="">
      <origin rpy="1.570795 0 0" xyz="0 0 0"/>
      <geometry>
        <cylinder length="0.1" radius="0.2"/>
      </geometry>
      <material name="black">
        <color rgba="0.05 0.05 0.05 1"/>
        <texture filename=""/>
      </material>
    </visual>
    <collision>
      <origin rpy="1.570795 0 0" xyz="0 0 0"/>
      <geometry>
        <cylinder length="0.1" radius="0.2"/>
      </geometry>
    </collision>
  </link>
  <joint name="joint_b_r_wheel" type="continuous">
    <parent link="base_link"/>
    <child link="b_r_wheel"/>
    <origin rpy="0 0 0" xyz="-0.25 -0.30 0"/>
    <axis rpy="0 0 0" xyz="0 1 0"/>
  </joint>
  <gazebo reference="b_r_wheel_trans_gaz">
    <mu1 value="200.0"/>
    <mu2 value="100.0"/>
    <kp value="10000000.0"/>
    <kd value="1.0"/>
    <material>Gazebo/Grey</material>
  </gazebo>
  <transmission name="trnasm_b_r_wheel">
    <type>transmission_interface/SimpleTransmission</type>
    <actuator name="$act_b_r_wheel">
      <mechanicalReduction>1</mechanicalReduction>
    </actuator>
    <joint name="joint_b_r_wheel">
      <hardwareInterface>VelocityJointInterface</hardwareInterface>
    </joint>
  </transmission>
  <link name="f_l_wheel">
    <inertial>
      <origin rpy="1.570795 0 0" xyz="0 0 0"/>
      <mass value="1.0"/>
      <inertia ixx="0.0" ixy="0.0" ixz="0.0" iyy="0.0" iyz="0.0" izz="0.0"/>
    </inertial>
    <visual name="">
      <origin rpy="1.570795 0 0" xyz="0 0 0"/>
      <geometry>
        <cylinder length="0.1" radius="0.2"/>
      </geometry>
      <material name="black">
        <color rgba="0.05 0.05 0.05 1"/>
        <texture filename=""/>
      </material>
    </visual>
    <collision>
      <origin rpy="1.570795 0 0" xyz="0 0 0"/>
      <geometry>
        <cylinder length="0.1" radius="0.2"/>
      </geometry>
    </collision>
  </link>
  <joint name="joint_f_l_wheel" type="continuous">
    <parent link="base_link"/>
    <child link="f_l_wheel"/>
    <origin rpy="0 0 0" xyz="0.25 0.30 0"/>
    <axis rpy="0 0 0" xyz="0 1 0"/>
  </joint>
  <gazebo reference="f_l_wheel_trans_gaz">
    <mu1 value="200.0"/>
    <mu2 value="100.0"/>
    <kp value="10000000.0"/>
    <kd value="1.0"/>
    <material>Gazebo/Grey</material>
  </gazebo>
  <transmission name="trnasm_f_l_wheel">
    <type>transmission_interface/SimpleTransmission</type>
    <actuator name="$act_f_l_wheel">
      <mechanicalReduction>1</mechanicalReduction>
    </actuator>
    <joint name="joint_f_l_wheel">
      <hardwareInterface>VelocityJointInterface</hardwareInterface>
    </joint>
  </transmission>
  <link name="b_l_wheel">
    <inertial>
      <origin rpy="1.570795 0 0" xyz="0 0 0"/>
      <mass value="1.0"/>
      <inertia ixx="0.0" ixy="0.0" ixz="0.0" iyy="0.0" iyz="0.0" izz="0.0"/>
    </inertial>
    <visual name="">
      <origin rpy="1.570795 0 0" xyz="0 0 0"/>
      <geometry>
        <cylinder length="0.1" radius="0.2"/>
      </geometry>
      <material name="black">
        <color rgba="0.05 0.05 0.05 1"/>
        <texture filename=""/>
      </material>
    </visual>
    <collision>
      <origin rpy="1.570795 0 0" xyz="0 0 0"/>
      <geometry>
        <cylinder length="0.1" radius="0.2"/>
      </geometry>
    </collision>
  </link>
  <joint name="joint_b_l_wheel" type="continuous">
    <parent link="base_link"/>
    <child link="b_l_wheel"/>
    <origin rpy="0 0 0" xyz="-0.25 0.30 0"/>
    <axis rpy="0 0 0" xyz="0 1 0"/>
  </joint>
  <gazebo reference="b_l_wheel_trans_gaz">
    <mu1 value="200.0"/>
    <mu2 value="100.0"/>
    <kp value="10000000.0"/>
    <kd value="1.0"/>
    <material>Gazebo/Grey</material>
  </gazebo>
  <transmission name="trnasm_b_l_wheel">
    <type>transmission_interface/SimpleTransmission</type>
    <actuator name="$act_b_l_wheel">
      <mechanicalReduction>1</mechanicalReduction>
    </actuator>
    <joint name="joint_b_l_wheel">
      <hardwareInterface>VelocityJointInterface</hardwareInterface>
    </joint>
  </transmission>
  <!-- Gazebo plugin for ROS Control -->
  <gazebo>
    <plugin filename="libgazebo_ros_control.so" name="gazebo_ros_control">
      <robotNamespace>/mugator_manip</robotNamespace>
      <robotSimType>gazebo_ros_control/DefaultRobotHWSim</robotSimType>
      <legacyModeNS>true</legacyModeNS>
    </plugin>
  </gazebo>
</robot>
<!-- <gazebo>
    <plugin name="gazebo_ros_control" filename="libgazebo_ros_control.so">
      <robotNamespace>/</robotNamespace>
    </plugin>
  </gazebo> -->

